Workbook

Sheet MEMBRESIA
E1: Dig.·. Resp.·. Abn.·. y Sesquicent.·. Log.·. Simb.·. FRATERNIDAD No. 1
B2: MEMBRESÍA Y CONTROL DE APORTACIONES 2 0 2 6
C3: PRICA | D3: AGO | E3: SEP | F3: OCT | G3: NOV | H3: NOV | I3: DIC | J3: ENE | K3: FEB | L3: MAR | M3: ABR | N3: MAY | O3: JUN | P3: JUL | Q3: AGO | R3: SEP | S3: OCT | T3: NOV | U3: DIC | V3: ADEUDO | W3: A FAVOR
A4: 1 | B4: DAVID GARCIA MELGOZA | J4: 1 | K4: 15 | L4: 24 | M4: 47 | N4: 59 | O4: 59 | P4: 73 | Q4: 73 | Z4: 1 | AA4: 21 | AB4: 41 | AC4: 61
A5: 2 | B5: GABINO S. SANTAMARIA DELGADO | J5: 9 | K5: 10 | L5: 23 | M5: 50 | N5: 58 | O5: 65 | P5: 71 | Z5: 2 | AA5: 22 | AB5: 42 | AC5: 62
A6: 3 | B6: JORGE L. MENDOZA SORIANO | J6: 11 | K6: 11 | L6: 39 | M6: 39 | N6: 54 | O6: 54 | Z6: 3 | AA6: 23 | AB6: 43 | AC6: 63
A7: 4 | B7: LEOPOLDO GARCIA MELGOZA | J7: 7 | K7: 34 | L7: 40 | M7: 49 | N7: x | O7: X | Z7: 4 | AA7: 24 | AB7: 44 | AC7: 64
A8: 5 | B8: LUIS RODRIGUEZ MATA | J8: 21 | K8: 21 | L8: 21 | M8: 48 | N8: 48 | O8: 48 | Z8: 5 | AA8: 25 | AB8: 45 | AC8: 65
A9: 6 | B9: L. ENRIQUE RAMON VILABOA | C9: 128 | J9: 14 | K9: 14 | L9: 14 | M9: 14 | N9: 14 | O9: 66 | P9: 67 | Q9: 67 | R9: 67 | S9: 67 | T9: 67 | Z9: 6 | AA9: 26 | AB9: 46 | AC9: 66
A10: 7 | B10: AULIO C. IBARRA ZAVALA | J10: 8 | K10: 8 | L10: 37 | M10: 37 | N10: 52 | O10: 52 | P10: 72 | Q10: 72 | Z10: 7 | AA10: 27 | AB10: 47 | AC10: 67
A11: 8 | B11: GUILLERMO F. MOTOLINIA SANCHEZ | C11: 43 | J11: 43 | K11: 43 | L11: 43 | M11: 43 | N11: 43 | O11: X | Z11: 8 | AA11: 28 | AB11: 48 | AC11: 68
A12: 9 | B12: JOSE A. GONZALEZ SOLIS | I12: 16 | J12: 16 | K12: 16 | L12: 41 | M12: 53 | N12: 70 | O12: 70 | V12: 350 | Z12: 9 | AA12: 29 | AB12: 49 | AC12: 69
A13: 10 | B13: J. OMAR PACHECO TAPIA | J13: 17 | K13: 17 | L13: 32 | M13: 44 | N13: 56 | O13: 64 | P13: 69 | Z13: 10 | AA13: 30 | AB13: 50 | AC13: 70
A14: 11 | B14: RAFAEL MARTINEZ DE JESUS | J14: 13 | K14: 13 | L14: 13 | M14: 13 | N14: 13 | O14: 13 | P14: 20 | Q14: 20 | R14: 20 | S14: 20 | T14: 20 | U14: 31 | Z14: 11 | AA14: 31 | AB14: 51 | AC14: 71
A15: 12 | B15: VICTOR H. AMBROSIO GUEVARA | C15: 26 | I15: 12 | J15: 2 | K15: 26 | L15: 36 | M15: 36 | N15: 57 | O15: 57 | Z15: 12 | AA15: 32 | AB15: 52 | AC15: 72
A16: 13 | B16: ALEXIS GARCIA ROBLES | J16: 33 | K16: 33 | L16: 42 | M16: 51 | N16: 60 | O16: 68 | Z16: 13 | AA16: 33 | AB16: 53 | AC16: 73
A17: 14 | B17: ANGEL R. GUTIERREZ ALVAREZ | J17: 19 | K17: 19 | L17: 19 | M17: 61 | N17: 61 | O17: 61 | P17: 62 | Q17: 62 | R17: 62 | V17: 350 | Z17: 14 | AA17: 34 | AB17: 54 | AC17: 74
A18: 15 | B18: A. RICARDO GUTIERREZ CONTRERAS | J18: 6 | K18: 22 | L18: 30 | M18: 45 | N18: 55 | O18: 63 | Z18: 15 | AA18: 35 | AB18: 55 | AC18: 75
B19: JOSMAR G. CANCHE HERMANDEZ | C19: 4 | D19: 4 | E19: 4 | F19: 4 | G19: 4 | I19: 4 | J19: 5 | K19: 5 | L19: 46 | M19: BAJA EN ABRIL | Z19: 16 | AA19: 36 | AB19: 56 | AC19: 76
B20: L. ELISEO JUAREZ MORALES | C20: 128 | I20: 18 | J20: 18 | K20: 25 | L20: X | M20: X | N20: BAJA EN MAYO | V20: 700 | Z20: 17 | AA20: 37 | AB20: 57 | AC20: 77
B21: L. MANUEL SANCHEZ TELLEZ | H21: 35 | I21: 35 | J21: x | K21: x | L21: X | M21: BAJA EN MARZO | V21: 1050 | Z21: 18 | AA21: 38 | AB21: 58 | AC21: 78
K22: DATOS AL 23 DE MARZO 2026 | Z22: 19 | AA22: 39 | AB22: 59 | AC22: 79
D23: PAGADO Y NUMERO DE RECIBO | Z23: 20 | AA23: 40 | AB23: 60 | AC23: 80

Sheet INGRESOS Y EGRESOS
D1: Dig.·. Resp.·. Abn.·. y Sesquicent.·. Log.·. Simb.·. FRATERNIDAD No. 1
B3: INGRESOS Y EGRESOS DEL MES DE ENERO 2026
B4: CAPITAS: | C4: 300 | E4: ANIVERSARIO: | G4: 50 | I4: MIEMBROS | J4: 18
E6: I N G R E S O S | J6: ENERO DE 2026
A7: RECIBO | B7: M I E M B R O | E7: CAPITAS | F7: ANIV. | G7: SACO BEN. | H7: TALLER B.J. | I7: OTROS | J7: TOTAL | K7: FECHA | L7: DESCRIPCION
A8: S/N | B8: SACO BENEFICENCIA | E8: 0 | F8: 0 | G8: 372 | H8: 0 | I8: 0 | J8: =SUM(E8+F8+G8+H8+I8) -> 372 | K8: 46035 | L8: INSTALACION C.L.
B9: SACO BENEFICENCIA | G9: 147 | J9: =SUM(E9+F9+G9+H9+I9) -> 147 | K9: 46042
B10: SACO BENEFICENCIA | G10: 190 | I10: 0 | J10: =SUM(E10+F10+G10+H10+I10) -> 190 | K10: 46049
A11: 001 | B11: DAVID GARCIA MELGOZA | E11: 285 | F11: 50 | H11: 15 | J11: =SUM(E11+F11+G11+H11+I11) -> 350
A12: 002 | B12: VICTOR H. AMBROSIO GUEVARA | E12: 285 | F12: 50 | H12: 15 | J12: =SUM(E12+F12+G12+H12+I12) -> 350
A13: 003 | B13: LEOPOLDO GARCIA MELGOZA | E13: 5000 | I13: 0 | J13: =SUM(E13+F13+G13+H13+I13) -> 5000 | K13: 46049 | L13: SALDO DE CAPITAS DEL AÑO PASADO
A14: 004 | B14: JOSMAR G. CANCHÉ HERNANDEZ | E14: 1050 | F14: 250 | I14: 128 | J14: =SUM(E14+F14+G14+H14+I14) -> 1428 | K14: 46052 | L14: CAP. AGO-DIC/2025 APOYO POZA RICA
A15: 005 | B15: JOSMAR G. CANCHÉ HERNANDEZ | E15: 570 | F15: 100 | H15: 30 | I15: 0 | J15: =SUM(E15+F15+G15+H15+I15) -> 700 | K15: 46052 | L15: ENE-FEB 2026
A16: 006 | B16: ANGEL R. GUTIERREZ CONTRERAS | E16: 285 | F16: 50 | H16: 15 | J16: =SUM(E16+F16+G16+H16+I16) -> 350 | K16: 46052
J17: =SUM(E17+F17+G17+H17+I17) -> 0
E18: =SUM(E8:E17) -> 7475 | F18: =SUM(F8:F17) -> 500 | G18: =SUM(G8:G17) -> 709 | H18: =SUM(H8:H17) -> 75 | I18: =SUM(I8:I17) -> 128 | J18: =SUM(E18+F18+G18+H18+I18) -> 8887
C21: EGRESOS
A22: No. | B22: C O N C E P T O | E22: CUENTA DE CARGO | K22: FECHA | L22: JUSTIFICACION
E23: CAPITAS | F23: ANIVERS. | G23: SACO BENE | H23: TALLER B.J. | I23: OTROS | J23: TOTAL
A24: 1 | B24: PAGO A LA GRAN LOGIA ENERO 2026 | E24: 5584 | K24: 46056
A25: 2 | B25: COPIAS DE RECIBOS LOGIA | E25: 90
E29: =SUM(E24:E28) -> 5674 | F29: =SUM(F24:F28) -> 0 | G29: =SUM(G24:G28) -> 0 | H29: =SUM(H24:H28) -> 0 | I29: =SUM(I24:I28) -> 0 | J29: =E29+F29+G29+H29+I29 -> 5674
H31: REMANENTE DEL MES | J31: =J18-J29 -> 3213
B34: ELABORÓ | E34: REVISÓ | J34: AUTORIZÓ
B36: DAVID GARCIA MELGOZA | E36: LEOPOLDO GARCIA MELGOZA | J36: GABINO S. SANTAMARIA DELGADO
B37: TES:. | E37: PDTE. COMISION DE HDA. | J37: VEN:. MAES:.
D66: Dig.·. Resp.·. Abn.·. y Sesquicent.·. Log.·. Simb.·. FRATERNIDAD No. 1
B68: INGRESOS Y EGRESOS DEL MES DE FEBRERO 2026
B69: CAPITAS: | C69: 300 | E69: ANIVERSARIO: | G69: 50 | I69: MIEMBROS | J69: 18
E71: I N G R E S O S
A72: RECIBO | B72: M I E M B R O | E72: CAPITAS | F72: ANIV. | G72: SACO BEN. | H72: TALLER B.J. | I72: OTROS | J72: TOTAL | K72: FECHA | L72: DESCRIPCION
A73: S/N | B73: SACO BENEFICENCIA | E73: 0 | F73: 0 | G73: 190 | H73: 0 | I73: 0 | J73: =SUM(E73+F73+G73+H73+I73) -> 190 | K73: 46056
A74: N7 | B74: LEOPOLDO GARCIA M. | E74: 285 | F74: 50 | G74: 0 | H74: 15 | I74: 0 | J74: =SUM(E74+F74+G74+H74+I74) -> 350 | K74: 46056 | L74: PAGO ENERO 2026
A75: N8 | B75: AULIO C. IBARRA Z. | E75: 570 | F75: 100 | H75: 30 | J75: =SUM(E75+F75+G75+H75+I75) -> 700 | K75: 46056 | L75: PAGO ENE-FEB 26
A76: N9 | B76: GABINO S.SANTAMARIA D. | E76: 285 | F76: 50 | H76: 15 | J76: =SUM(E76+F76+G76+H76+I76) -> 350 | K76: 46056 | L76: PAGO ENERO 2026
A77: 10 | B77: GABINO S.SANTAMARIA D. | E77: 285 | F77: 50 | H77: 15 | J77: =SUM(E77+F77+G77+H77+I77) -> 350 | K77: 46063 | L77: PAGO FEB 2026
A78: 11 | B78: JORGE L.MENDOZA S. | E78: 570 | F78: 100 | H78: 30 | J78: =SUM(E78+F78+G78+H78+I78) -> 700 | K78: 46063 | L78: PAGO ENE-FEB 26
A79: 12 | B79: VICTOR H. AMBROSIO G. | E79: 250 | F79: 50 | H79: 0 | J79: =SUM(E79+F79+G79+H79+I79) -> 300 | K79: 46063 | L79: PAGO DIC 2025
A80: S/N | B80: SACO BENEFICENCIA | G80: 250 | J80: =SUM(E80+F80+G80+H80+I80) -> 250 | K80: 46063
A81: 13 | B81: RAFAEL MARTINEZ DE J. | E81: 1710 | F81: 300 | H81: 90 | J81: =SUM(E81+F81+G81+H81+I81) -> 2100 | K81: 46063 | L81: PAGO ENE-JUN 26
...

Sheet INFORME MENS
C3: INFORME MENSUAL DE RESULTADOS FINANCIEROS
B4: MIEMBROS ACTIVOS | D4: 18 | E4: FECHA: | F4: ENERO 2026
C6: CAPITAS
B7: INGRESO | C7: MES ANT. | D7: SUB TOTAL | E7: EGRESO | G7: SALDO TOTAL
B8: ='INGRESOS Y EGRESOS'!E18 -> 7475 | C8: 0 | D8: =B8+C8 -> 7475 | E8: ='INGRESOS Y EGRESOS'!E29 -> 5674 | G8: =D8-E8 -> 1801
C10: ANIVERSARIO
B11: INGRESOS | C11: MES ANT. | D11: SUB TOTAL | E11: EGRESO | G11: SALDO TOTAL
B12: ='INGRESOS Y EGRESOS'!F18 -> 500 | C12: 0 | D12: =B12+C12 -> 500 | E12: 0 | G12: =D12-E12 -> 500
C14: SACO DE BENEFICENCIA
B15: INGRESOS | C15: MES ANT. | D15: SUB TOTAL | E15: EGRESO | G15: SALDO TOTAL
B16: 709 | D16: =B16+C16 -> 709 | E16: 0 | G16: =D16-E16 -> 709
C18: T A L L E R B E N I T O J U A R E Z
B19: INGRESOS | C19: MES ANT. | D19: SUB TOTAL | E19: EGRESO | G19: SALDO TOTAL
B20: 75 | C20: 0 | D20: =B20+C20 -> 75 | E20: 0 | G20: =D20-E20 -> 75
C22: OTROS (Poza Rica)
B23: INGRESOS | C23: MES ANT. | D23: SUB TOTAL | E23: EGRESO | G23: SALDO TOTAL
B24: 128 | C24: 0 | D24: =B24+C24 -> 128 | E24: 0 | G24: =D24-E24 -> 128
E27: SUMA TOTAL | G27: =G8+G12+G16+G20+G24 -> 3213
B30: ELABORÓ | D30: REVISÓ | G30: AUTORIZÓ
A32: DAVID GARCIA MELGOZA | D32: LEOPOLDO GARCIA MELGOZA | G32: GABINO S. SANTAMARIA DELGADO
B33: TES:. | D33: PRESIDENTE COM. HDA. | G33: VEN:. MAES:.
C47: INFORME MENSUAL DE RESULTADOS FINANCIEROS
B48: MIEMBROS ACTIVOS | D48: 18 | E48: FECHA: | F48: FEBRERO 2026
C50: CAPITAS
B51: INGRESO | C51: MES ANT. | D51: SUB TOTAL | E51: EGRESO | G51: SALDO TOTAL
B52: ='INGRESOS Y EGRESOS'!E89 -> 9550 | C52: =G8 -> 1801 | D52: =B52+C52 -> 11351 | E52: ='INGRESOS Y EGRESOS'!E100 -> 4844 | G52: =D52-E52 -> 6507
C54: ANIVERSARIO
B55: INGRESOS | C55: MES ANT. | D55: SUB TOTAL | E55: EGRESO | G55: SALDO TOTAL
B56: ='INGRESOS Y EGRESOS'!F89 -> 1650 | C56: =G12 -> 500 | D56: =B56+C56 -> 2150 | E56: 0 | G56: =D56-E56 -> 2150
C58: SACO DE BENEFICENCIA
B59: INGRESOS | C59: MES ANT. | D59: SUB TOTAL | E59: EGRESO | G59: SALDO TOTAL
B60: ='INGRESOS Y EGRESOS'!G89 -> 440 | C60: =G16 -> 709 | D60: =B60+C60 -> 1149 | E60: 0 | G60: =D60-E60 -> 1149
C62: T A L L E R B E N I T O J U A R E Z
B63: INGRESOS | C63: MES ANT. | D63: SUB TOTAL | E63: EGRESO | G63: SALDO TOTAL
B64: ='INGRESOS Y EGRESOS'!H89 -> 450 | C64: =G20 -> 75 | D64: =B64+C64 -> 525 | E64: 0 | G64: =D64-E64 -> 525
C66: OTROS (Poza Rica)
B67: INGRESOS | C67: MES ANT. | D67: SUB TOTAL | E67: EGRESO | G67: SALDO TOTAL
B68: ='INGRESOS Y EGRESOS'!I89 -> 0 | C68: =G24 -> 128 | D68: =B68+C68 -> 128 | E68: 0 | G68: =D68-E68 -> 128
E71: SUMA TOTAL | G71: =G52+G56+G60+G64+G68 -> 10459
B74: ELABORÓ | D74: REVISÓ | G74: AUTORIZÓ
...

Sheet PAGO A GLUM
C3: Dig.·. Resp.·. Abn.·. y Sesquicent.·. Log.·. Simb.·. FRATERNIDAD No. 1
A4: REMESA DE FONDOS MENSUAL QUE SE RINDE EN CUMPLIMIENTO DE LO QUE DISPONE EL ART. 60 DEL REGLAMENTO DE LA GR:. LOG:.
F5: "UNIDA MEXICANA" Y DE LL:. Y AA:. MM:. DEL GR:. OR:. DE VERACRUZ
B7: RESP:. LOG:. SIMB:. | D7: FRATERNIDAD No. 1
B8: MES : | C8: MARZO 2026
B9: DETALLE DE LA APLICACIÓN | J9: AUX:. MAS:. "POST MORTEM"
B10: CAPITAS | I10: GRAN LOGIA
F11: MES | G11: HH:. | H11: COSTO
B13: MENSUAL | F13: 1 | G13: 17 | H13: 120 | I13: =F13*G13*H13 -> 2040
B14: DERECHOS
B15: INICIACIONES | G15: 0 | H15: 250 | I15: =G15*H15 -> 0
B16: AUMENTO DE SALARIO | G16: 0 | H16: 250 | I16: =G16*H16 -> 0
B17: EXALTACIONES | G17: 0 | H17: 250 | I17: =G17*H17 -> 0
B18: REGULARIZACIONES | G18: 0 | H18: 250 | I18: =G18*H18 -> 0
B19: AFILIACION | G19: 0 | H19: 250 | I19: =G19*H19 -> 0
B21: DIVERSOS
B23: REVISTA UNIDAD MEXICANA (SIMBOLISMO) | F23: =F13 -> 1 | G23: =G13 -> 17 | H23: 18 | I23: =F23*G23*H23 -> 306
B24: CONF:. GGR:. LLOG:. REP.MEX. | F24: 1 | G24: --- | H24: 150 | I24: =F24*H24 -> 150
B25: CONF:. MAS:. INTERAMERICANA | F25: 1 | G25: --- | H25: 70 | I25: =F25*H25 -> 70
B26: SERVICIOS | F26: =F13 -> 1 | G26: --- | H26: 800 | I26: =F26*H26 -> 800
B28: OTROS: FONDO DE CONTINGENCIA | F28: 0 | G28: --- | H28: 500 | I28: =F28*H28 -> 0
B30: AUX:. MAS:. "POST MORTEM"
B32: CUOTAS INICIALES | G32: 0 | H32: 150 | J32: =G32*H32 -> 0
B33: CUOTAS MENSUALES | F33: 1 | G33: =G13 -> 17 | H33: 10 | J33: =F33*G33*H33 -> 170
B34: DEFUNCION No. DEL | C34: 2759 | D34: AL | E34: 2759 | F34: 1 | G34: =G13 -> 17 | H34: 50 | J34: =F34*G34*H34 -> 850
H35: SUBTOTAL | I35: =SUM(I13:I34) -> 3366 | J35: =SUM(J13:J34) -> 1020
H36: TOTAL | I36: =I35+J35 -> 4386
C38: MIEMBROS ACTIVOS | G38: ALTAS EN EL MES | J38: MOVIMIENTOS EN EL MES
C40: 6 | D40: MAESTROS | G40: 0 | H40: INIC. | J40: 0 | K40: AUM. SAL
C41: 6 | D41: COMPAÑEROS | G41: 0 | H41: AFIL. | J41: 0 | K41: EXALT
C42: 5 | D42: APRENDICES | G42: 0 | H42: REG. | J42: =J40+J41 -> 0 | K42: TOTAL
C43: =C40+C41+C42 -> 17 | D43: TOTAL | G43: =G40+G41+G42 -> 0 | H43: TOTAL
C45: BAJAS EN EL MES | J45: OTROS
C46: 0 | D46: BORRADOS POR FALTAS REGLAMENTARIAS | J46: 0 | K46: M.L.O.
C47: 0 | D47: SEPARADOS POR PL:. DE QUITE | J47: 0 | K47: M. ALT. CAM
C48: =C46+C47 -> 0 | D48: TOTAL | J48: =J46+J47 -> 0 | K48: TOTAL
C50: RESUMEN
C51: 18 | D51: MMIEMB.ACTI. MES ANTERIOR
C52: 18 | D52: MMIEMB.ACTI. PRESENTE MES
C53: 0 | D53: DIFERENCIA HH:. DEL TALLER
...

Sheet DEFUNCIONES
D1: Dig.·. Resp.·. Abn.·. y Sesquicent.·. Log.·. Simb.·. FRATERNIDAD No. 1
D2: D E F U N C I O N E S
D3: 2 0 2 6
A4: No. | B4: GRAN CIRC. | C4: FECHA | D4: DEFUNC | E4: NOMBRE | F4: LOGIA | G4: ORIENTE | H4: PAGADO
A5: 1 | B5: 17/2025 | C5: 46036 | D5: 2753 | E5: JESUS MARTIN CARRION BRAVO | F5: YANGA No. 15 | G5: CORDOBA, VER | H5: 45899
A6: 2 | B6: 18/2025 | C6: 46036 | D6: 2754 | E6: MARCELINO CEBALLOS ZAMARRON | F6: FRATERNIDAD No. 11 | G6: JALAPA, VER. | H6: 45930
A7: 3 | B7: 19/2026 | C7: 46045 | D7: 2755 | E7: VICTOR MANUEL ESPINOZA BASTIAN | F7: MAHATMA GANDHI No. 3 | G7: POZA RICA, Ver. | H7: 45960
A8: 4 | B8: 20/2026 | C8: 46046 | D8: 2756 | E8: EFREN USCANGA BRAVO | F8: CATEMACO No. 68 | G8: CATEMACO, VER. | H8: 45986
A9: 5 | B9: 29/2026 | C9: 46092 | D9: 2757 | E9: JUAN CARLOS ENCISO MENDEZ | F9: DEP. DEL OTE. 17 | G9: JALAPA, VER. | H9: 46053
A10: 6 | B10: 40/2026 | C10: 265330 | D10: 2758 | E10: MARIO RODRIGUEZ CASTELLANOS | F10: FRATER Y PROG 50 | G10: TUXPAN, VER. | H10: 46080
D11: 2759 | H11: 46111
D12: 2760 | H12: 46140
D13: 2761 | H13: 46201
